<?xml version="1.0"?>
<robot xmlns:sensor="http://playerstage.sourceforge.net/gazebo/xmlschema/#sensor"
       xmlns:controller="http://playerstage.sourceforge.net/gazebo/xmlschema/#controller"
       xmlns:interface="http://playerstage.sourceforge.net/gazebo/xmlschema/#interface"
       xmlns:xacro="http://ros.org/wiki/xacro">

	<xacro:include filename="$(find youbot_description)/urdf/youbot_gripper/gripper.gazebo.xacro" />
	<xacro:include filename="$(find youbot_description)/urdf/youbot_gripper/gripper.transmission.xacro" />
	<xacro:include filename="$(find youbot_description)/urdf/youbot_gripper/limits.urdf.xacro" />

	<xacro:macro name="youbot_gripper" params="parent name *origin">
	<xacro:property name="holder" value="0.4"/>

		<!-- joint between arm_7_link and sdh_palm_link -->
		<joint name="${name}_palm_joint" type="fixed" >
			<xacro:insert_block name="origin" />
			<parent link="${parent}" />
			<child link="${name}_palm_link" />
		</joint>

		<link name="${name}_palm_link">
			<inertial>
				<origin xyz="0 0 0" rpy="0 0 0"/>
				<mass value="0.1"/>
				<inertia ixx="0.01" ixy="0" ixz="0" iyy="0.01" iyz="0" izz="0.01" />
			</inertial>
			
			<visual>
				<origin xyz="0 0 0" rpy="0 0 0" />
				<geometry>
					<mesh filename="package://youbot_description/meshes/youbot_gripper/palm.dae" />
				</geometry>
				<material name="Black" />
			</visual>
			
			<collision>
				<origin xyz="0 0 0" rpy="0 0 0" />
				<geometry>
					<!--<box size="0.050 0.094 0.054"/>-->
					<mesh filename="package://youbot_description/meshes/youbot_gripper/palm_convex.dae" />
				</geometry>
			</collision>
		</link>
		<link name="d435i_holder">
		     <inertial>
			<mass value="${holder}"/>
			<origin rpy="0 0 1.57" xyz="0 0 0"/>
			<inertia ixx="0.012411765597" ixy="-0.000711733678" ixz="0.00050272983" iyy="0.015218160428" iyz="-0.000004273467" izz="0.011763977943"/>
		</inertial>
			<visual>
			<geometry>
                <mesh filename = "package://urdf_tutorial/meshes/collision/d435i_holder_v7.stl"/>
			</geometry>
			<material name="White"/>
			</visual>
		</link>

		<joint name="d435i_holder" type="fixed">
			<parent link="${name}_palm_link"/>
			<child link="d435i_holder"/>
			<origin rpy="-1.57 -1.57 1.57" xyz="-0.045 -0.024 0.025"/>
		</joint>
		
		<link name="camera_link">
		     <inertial>
			<mass value="${holder}"/>
			<origin xyz="0 0 0" rpy="0 0 0" />
			<inertia ixx="0.012411765597" ixy="-0.000711733678" ixz="0.00050272983" iyy="0.015218160428" iyz="-0.000004273467" izz="0.011763977943"/>
		</inertial>
			<visual>
			<geometry>
                <mesh filename = "package://urdf_tutorial/meshes/collision/Intel Realsense D435i_v2.stl"/>
			</geometry>
			<material name="White"/>
			</visual>
		</link>

		<joint name="d435i" type="fixed">
			<parent link="d435i_holder"/>
			<child link="camera_link"/>
			<origin rpy="-1.57 3.14 -1.57" xyz="-0.005 0.022 0"/>
		</joint>
		
		<joint name="${name}_finger_joint_l" type="prismatic">
			<origin xyz="0.004 0.008 0.046" rpy="0 0 ${M_PI}" />
			<parent link="${name}_palm_link"/>
			<child link="${name}_finger_link_l"/>
			<axis xyz="0 -1 0" />
			
			<dynamics damping="1.0" friction="1.0" />
			<limit effort="1" velocity="0.1" lower="0" upper="${finger_joint}"/> 
                        <safety_controller k_position="20" k_velocity="25" soft_lower_limit="${threshold}" soft_upper_limit="${finger_joint_soft}" />
		</joint>

		<link name="${name}_finger_link_l">
			<inertial>
				<origin xyz="0 -0.001 0" rpy="0 0 0" />
				<mass value="0.01"/>
				<inertia ixx="0.01" ixy="0" ixz="0" iyy="0.01" iyz="0" izz="0.01" />
			</inertial>
			
			<visual>
				<origin xyz="0 0 0" rpy="0 0 0" />
				<geometry>
					<mesh filename="package://youbot_description/meshes/youbot_gripper/finger.dae" />
				</geometry>
				<material name="Black" />
			</visual>
			
			<collision>
				<origin xyz="0 0 0" rpy="0 0 0" />
				<geometry>
					<!--<box size="0.014 0.020 0.046"/>-->
					<mesh filename="package://youbot_description/meshes/youbot_gripper/finger_convex.dae" />
				</geometry>
			</collision>
		</link>

               <joint name="${name}_finger_joint_r" type="prismatic">
			<origin xyz="0.004 -0.008 0.046" rpy="0 0 0" />
			<parent link="${name}_palm_link"/>
			<child link="${name}_finger_link_r"/>
			<axis xyz="0 -1 0" />
			<dynamics damping="1.0" friction="1.0" />
			<limit effort="1" velocity="0.1" lower="0" upper="${finger_joint}"/> 
                        <safety_controller k_position="20" k_velocity="25" soft_lower_limit="${threshold}" soft_upper_limit="${finger_joint_soft}" />
		</joint>

		<link name="${name}_finger_link_r">
			<inertial>
				<origin xyz="0.000 -0.001 0" rpy="0 0 0" />
				<mass value="0.01"/>
				<inertia ixx="0.01" ixy="0" ixz="0" iyy="0.01" iyz="0" izz="0.01" />
			</inertial>
			
			<visual>
				<origin xyz="0 0 0" rpy="0 0 0" />
				<geometry>
					<mesh filename="package://youbot_description/meshes/youbot_gripper/finger.dae" />
				</geometry>
				<material name="Black" />
			</visual>
			
			<collision>
				<origin xyz="0.000 0 0" rpy="0 0 0" />
				<geometry>
					<!--<box size="0.014 0.020 0.046"/>-->
					<mesh filename="package://youbot_description/meshes/youbot_gripper/finger_convex.dae" />
				</geometry>
			</collision>
		</link>

		
		<!-- extensions -->
		<xacro:youbot_gripper_gazebo name="${name}" />
		<xacro:youbot_gripper_transmission name="${name}" />

	</xacro:macro>

</robot>
